{
    "config": {
        "abort": {
            "already_configured": "A szolg\u00e1ltat\u00e1s m\u00e1r konfigur\u00e1lva van",
            "bad_config": "A k\u00e9r\u00e9s sikertelen volt rossz konfigur\u00e1ci\u00f3 miatt: Ellen\u0151rizze a [menetrendet]({stationboard_url}) \u00e9rv\u00e9nyes \u00e1llom\u00e1sok\u00e9rt.",
            "cannot_connect": "Nem lehet kapcsol\u00f3dni a szerverhez",
            "unknown": "Ismeretlen hiba l\u00e9pett fel a python-opendata-transportban"
        },
        "error": {
            "bad_config": "A k\u00e9r\u00e9s sikertelen volt rossz konfigur\u00e1ci\u00f3 miatt: Ellen\u0151rizze a [menetrendet]({stationboard_url}) oldalon, hogy \u00e9rv\u00e9nyesek-e az \u00e1llom\u00e1snevek",
            "cannot_connect": "Nem lehet kapcsol\u00f3dni a szerverhez",
            "too_many_via_stations": "T\u00fal sok k\u00f6zbens\u0151 \u00e1llom\u00e1s, legfeljebb 5 k\u00f6zbens\u0151 \u00e1llom\u00e1s enged\u00e9lyezett kapcsolatk\u00e9nt.",
            "unknown": "Ismeretlen hiba l\u00e9pett fel a python-opendata-transportban"
        },
        "step": {
            "user": {
                "data": {
                    "from": "Indul\u00e1si \u00e1llom\u00e1s",
                    "to": "V\u00e9g\u00e1llom\u00e1s",
                    "via": "Legfeljebb 5 k\u00f6zbens\u0151 \u00e1llom\u00e1s list\u00e1ja"
                },
                "description": "Adja meg a kiindul\u00e1si \u00e9s v\u00e9g\u00e1llom\u00e1st az \u00fatvonal\u00e1hoz, valamint opcion\u00e1lisan legfeljebb 5 \u00e1tsz\u00e1ll\u00e1si \u00e1llom\u00e1st.\n\nA [menetrend]({stationboard_url}) seg\u00edts\u00e9g\u00e9vel ellen\u0151rizheti az \u00e9rv\u00e9nyes \u00e1llom\u00e1sokat.",
                "title": "Sv\u00e1jci t\u00f6megk\u00f6zleked\u00e9s"
            }
        }
    },
    "entity": {
        "sensor": {
            "delay": {
                "name": "K\u00e9s\u00e9s"
            },
            "departure": {
                "name": "Indul\u00e1s"
            },
            "departure0": {
                "name": "Indul\u00e1s"
            },
            "departure1": {
                "name": "Indul\u00e1s +1"
            },
            "departure2": {
                "name": "Indul\u00e1s +2"
            },
            "duration": {
                "name": "Id\u0151tartam"
            },
            "platform": {
                "name": "Platform"
            },
            "transfers": {
                "name": "\u00c1tsz\u00e1ll\u00e1sok"
            }
        }
    },
    "exceptions": {
        "cannot_connect": {
            "message": "Nem tud csatlakozni a kiszolg\u00e1l\u00f3hoz.\n{error}"
        },
        "config_entry_not_found": {
            "message": "A \" {target} \" sv\u00e1jci t\u00f6megk\u00f6zleked\u00e9si integr\u00e1ci\u00f3s p\u00e9ld\u00e1ny nem tal\u00e1lhat\u00f3."
        },
        "invalid_data": {
            "message": "A(z) {config_title} be\u00e1ll\u00edt\u00e1sa sikertelen az \u00e9rv\u00e9nytelen adatok miatt, ellen\u0151rizze a [menetrendben]({stationboard_url}), hogy az \u00e1llom\u00e1snevek \u00e9rv\u00e9nyesek-e.\n{error}"
        },
        "not_loaded": {
            "message": "{target} nincs bet\u00f6ltve."
        },
        "request_timeout": {
            "message": "Id\u0151t\u00fall\u00e9p\u00e9s a {config_title} bejegyz\u00e9s csatlakoz\u00e1sakor.\n{error}"
        }
    },
    "issues": {
        "deprecated_yaml_import_issue_bad_config": {
            "description": "A sv\u00e1jci t\u00f6megk\u00f6zleked\u00e9s YAML-ban t\u00f6rt\u00e9n\u0151 konfigur\u00e1l\u00e1sa megsz\u0171nik, de hib\u00e1s konfigur\u00e1ci\u00f3 ker\u00fclt import\u00e1l\u00e1sra a YAML konfigur\u00e1ci\u00f3j\u00e1ba.\n\nEllen\u0151rizze a [menetrend]({stationboard_url}) oldalon az \u00e9rv\u00e9nyes \u00e1llom\u00e1sokat.",
            "title": "A sv\u00e1jci t\u00f6megk\u00f6zleked\u00e9si YAML-konfigur\u00e1ci\u00f3 import\u00e1l\u00e1si k\u00e9relme hib\u00e1s konfigur\u00e1ci\u00f3 miatt meghi\u00fasult"
        },
        "deprecated_yaml_import_issue_cannot_connect": {
            "description": "A sv\u00e1jci t\u00f6megk\u00f6zleked\u00e9s YAML haszn\u00e1lat\u00e1val t\u00f6rt\u00e9n\u0151 konfigur\u00e1l\u00e1sa megsz\u0171nik, de hiba t\u00f6rt\u00e9nt a YAML konfigur\u00e1ci\u00f3d import\u00e1l\u00e1sa k\u00f6zben.\n\nGy\u0151z\u0151dj\u00f6n meg r\u00f3la, hogy a Home Assistant el tudja \u00e9rni az [opendata szervert]({opendata_url}). Ha a szerver nem m\u0171k\u00f6dik, pr\u00f3b\u00e1lja meg k\u00e9s\u0151bb \u00fajra.",
            "title": "A sv\u00e1jci t\u00f6megk\u00f6zleked\u00e9si YAML-konfigur\u00e1ci\u00f3 import\u00e1l\u00e1sa nem tud csatlakozni a kiszolg\u00e1l\u00f3hoz"
        },
        "deprecated_yaml_import_issue_unknown": {
            "description": "A sv\u00e1jci t\u00f6megk\u00f6zleked\u00e9s YAML haszn\u00e1lat\u00e1val val\u00f3 konfigur\u00e1l\u00e1sa megsz\u0171ni, de ismeretlen hiba t\u00f6rt\u00e9nt a YAML-konfigur\u00e1ci\u00f3 import\u00e1l\u00e1sakor.\n\nEllen\u0151rizze a konfigur\u00e1ci\u00f3t, vagy tekintse meg az integr\u00e1ci\u00f3 dokument\u00e1ci\u00f3j\u00e1t.",
            "title": "A sv\u00e1jci t\u00f6megk\u00f6zleked\u00e9si YAML-konfigur\u00e1ci\u00f3 import\u00e1l\u00e1sa sikertelen volt a python-opendata-transport \u00e1ltal okozott ismeretlen hiba miatt"
        }
    },
    "services": {
        "fetch_connections": {
            "description": "T\u00f6ltse le a csatlakoz\u00e1sok list\u00e1j\u00e1t a sv\u00e1jci t\u00f6megk\u00f6zleked\u00e9sb\u0151l.",
            "fields": {
                "config_entry_id": {
                    "description": "Sv\u00e1jci t\u00f6megk\u00f6zleked\u00e9si p\u00e9ld\u00e1ny, amelyhez kapcsolatokat kell lek\u00e9rni.",
                    "name": "P\u00e9ld\u00e1ny"
                },
                "limit": {
                    "description": "A lek\u00e9rdezend\u0151 kapcsolatok sz\u00e1ma [1-15]",
                    "name": "Korl\u00e1t"
                }
            },
            "name": "Kapcsolatok lek\u00e9r\u00e9se"
        }
    }
}